import React from 'react';
import { render, screen } from '@testing-library/react';
import { describe, it, expect, vi } from 'vitest';
import { ErrorBoundary } from '@/components/ErrorBoundary';

// Mock the logger
vi.mock('@/utils/logger', () => ({
  log: {
    error: vi.fn(),
  },
}));

// Component that throws an error for testing
const ThrowError = ({ shouldThrow }: { shouldThrow: boolean }) => {
  if (shouldThrow) {
    throw new Error('Test error');
  }
  return <div>No error</div>;
};

describe('ErrorBoundary', () => {
  it('renders children when there is no error', () => {
    render(
      <ErrorBoundary>
        <ThrowError shouldThrow={false} />
      </ErrorBoundary>
    );

    expect(screen.getByText('No error')).toBeInTheDocument();
  });

  it('renders default error fallback when error occurs', () => {
    render(
      <ErrorBoundary>
        <ThrowError shouldThrow={true} />
      </ErrorBoundary>
    );

    expect(screen.getByText('Noe gikk galt')).toBeInTheDocument();
    expect(screen.getByText('Vennligst prøv å laste siden på nytt.')).toBeInTheDocument();
  });

  it('renders custom fallback when provided', () => {
    const customFallback = <div>Custom error message</div>;

    render(
      <ErrorBoundary fallback={customFallback}>
        <ThrowError shouldThrow={true} />
      </ErrorBoundary>
    );

    expect(screen.getByText('Custom error message')).toBeInTheDocument();
    expect(screen.queryByText('Noe gikk galt')).not.toBeInTheDocument();
  });
});